<?xml version="1.0" ?>
<!-- =================================================================================== -->
<!-- |    This document was autogenerated by xacro from dory.xacro                     | -->
<!-- |    EDITING THIS FILE BY HAND IS NOT RECOMMENDED                                 | -->
<!-- =================================================================================== -->
<!-- Copyright (c) 2016 The UUV Simulator Authors.
     All rights reserved.

     Licensed under the Apache License, Version 2.0 (the "License");
     you may not use this file except in compliance with the License.
     You may obtain a copy of the License at

       http://www.apache.org/licenses/LICENSE-2.0

     Unless required by applicable law or agreed to in writing, software
     distributed under the License is distributed on an "AS IS" BASIS,
     WITHOUT WARRANTIES OR CONDITIONS OF ANY KIND, either express or implied.
     See the License for the specific language governing permissions and
     limitations under the License.
-->
<robot name="dory" xmlns:xacro="http://www.ros.org/wiki/xacro">
  <!-- Some pretty colors -->
  <material name="blue">
    <color rgba="0.0 0.0 0.8 1.0"/>
  </material>
  <material name="green">
    <color rgba="0.0 0.8 0.0 1.0"/>
  </material>
  <material name="grey">
    <color rgba="0.7 0.7 0.7 1.0"/>
  </material>
  <material name="grey2">
    <color rgba="0.9 0.9 0.9 1.0"/>
  </material>
  <material name="red">
    <color rgba="0.8 0.0 0.0 1.0"/>
  </material>
  <material name="orange">
    <color rgba="1.0 0.5 0.0 1.0"/>
  </material>
  <material name="white">
    <color rgba="1.0 1.0 1.0 1.0"/>
  </material>
  <material name="black">
    <color rgba="0.05 0.05 0.05 1.0"/>
  </material>

  <link name="dory/base_link">
    <inertial>
      <mass value="69"/>
      <origin xyz="0 0 0"/>
      <inertia ixx="2.16" ixy="0.0059" ixz="0.137" iyy="3.268" iyz="0.0107" izz="2.845"/>
      <!-- dimensions 3x smaller -> inertia = scale^5 -->
    </inertial>
    <visual>
      <origin rpy="1.5707961 0 0" xyz="-0.65 1.125 -0.8"/>
      <geometry>
        <mesh filename="file:///home/dfki.uni-bremen.de/mlodhi/WasteShark/catkin_ws/src/dory_description/meshes/dory_base.stl" scale="0.001 0.001 0.001"/>
      </geometry>
    </visual>
    <!-- bottom plate -->
    <collision>
      <origin rpy="0 0 0" xyz="0 0 -0.75"/>
      <geometry>
        <box size="2.56 1.50 0.10"/>
      </geometry>
    </collision>
    <!-- top plate -->
    <collision>
      <origin rpy="0 0 0" xyz="0 0 0.60"/>
      <geometry>
        <box size="2.56 1.50 0.40"/>
      </geometry>
    </collision>
    <!-- left / right sides -->
    <collision>
      <origin rpy="0 0 0" xyz="-0.20 0.70 -0.15"/>
      <geometry>
        <box size="2.20 0.10 1.10"/>
      </geometry>
    </collision>
    <collision>
      <origin rpy="0 0 0" xyz="-0.20 -0.70 -0.15"/>
      <geometry>
        <box size="2.20 0.10 1.10"/>
      </geometry>
    </collision>
  </link>

  <joint name="dory/thruster_1_joint" type="continuous">
    <origin rpy="0.0 0.0 3.1415922" xyz="-0.5 0.3 -0.1"/>
    <axis xyz="1 0 0"/>
    <parent link="dory/base_link"/>
    <child link="dory/thruster_1"/>
  </joint>
  <link name="dory/thruster_1">
    <inertial>
      <mass value="0.001"/>
      <origin rpy="0 0 0" xyz="0 0 0"/>
      <inertia ixx="0.0" ixy="0.0" ixz="0.0" iyy="0.0" iyz="0.0" izz="0.0"/>
    </inertial>
    <visual>
      <origin rpy="0 0 0" xyz="0 0 0"/>
      <geometry>
        <mesh filename="file:///home/dfki.uni-bremen.de/mlodhi/WasteShark/catkin_ws/src/uuv_simulator/uuv_descriptions/models/dory/mesh/prop.dae" scale="1 1 1"/>
      </geometry>
    </visual>
    <collision>
      <geometry>
        <cylinder length="0.000001" radius="0.000001"/>
      </geometry>
      <origin rpy="0 0 0" xyz="0 0 0"/>
    </collision>
  </link>
  <joint name="dory/thruster_2_joint" type="continuous">
    <origin rpy="0.0 0.0 3.1415922" xyz="-0.5 -0.3 -0.1"/>
    <axis xyz="1 0 0"/>
    <parent link="dory/base_link"/>
    <child link="dory/thruster_2"/>
  </joint>
  <link name="dory/thruster_2">
    <inertial>
      <mass value="0.001"/>
      <origin rpy="0 0 0" xyz="0 0 0"/>
      <inertia ixx="0.0" ixy="0.0" ixz="0.0" iyy="0.0" iyz="0.0" izz="0.0"/>
    </inertial>
    <visual>
      <origin rpy="0 0 0" xyz="0 0 0"/>
      <geometry>
        <mesh filename="file:///home/dfki.uni-bremen.de/mlodhi/WasteShark/catkin_ws/src/uuv_simulator/uuv_descriptions/models/dory/mesh/prop.dae" scale="1 1 1"/>
      </geometry>
    </visual>
    <collision>
      <!-- todo: gazebo needs a collision volume or it will ignore the pose of
           the joint that leads to this link (and assume it to be the identity) -->
      <geometry>
        <cylinder length="0.000001" radius="0.000001"/>
      </geometry>
      <origin rpy="0 0 0" xyz="0 0 0"/>
    </collision>
  </link>

  <!-- Sensor link -->
  <link name="dory/magnetometer_link">
    <inertial>
      <inertia ixx="0.00001" ixy="0.0" ixz="0.0" iyy="0.00001" iyz="0.0" izz="0.00001"/>
      <mass value="0.015"/>
      <origin rpy="0 0 0" xyz="0 0 0"/>
    </inertial>
    <visual>
      <geometry>
        <box size="0.1 0.1 0.1"/>
      </geometry>
    </visual>
    <collision>
      <geometry>
        <cylinder length="1e-06" radius="1e-06"/>
      </geometry>
      <origin rpy="0 1.57079632679 0" xyz="0 0 0"/>
    </collision>
  </link>
  <!-- Sensor joint -->
  <joint name="dory/magnetometer_joint" type="revolute">
    <origin rpy="0 0 0" xyz="0 0 0"/>
    <parent link="dory/base_link"/>
    <child link="dory/magnetometer_link"/>
    <limit effort="0" lower="0" upper="0" velocity="0"/>
    <axis xyz="1 0 0"/>
  </joint>

  <!-- IMU link -->
  <link name="dory/imu_link">
    <inertial>
      <inertia ixx="0.00001" ixy="0.0" ixz="0.0" iyy="0.00001" iyz="0.0" izz="0.00001"/>
      <mass value="0.015"/>
      <!-- [kg] -->
      <origin rpy="0 0 0" xyz="0 0 0"/>
    </inertial>
  </link>
  <!-- IMU joint -->
  <joint name="dory/imu_joint" type="revolute">
    <origin rpy="0 0 0" xyz="0 0 0"/>
    <parent link="dory/base_link"/>
    <child link="dory/imu_link"/>
    <limit effort="0" lower="0" upper="0" velocity="0"/>
    <axis xyz="1 0 0"/>
  </joint>
  <!-- Sensor link -->
  <link name="dory/camera_link">
    <inertial>
      <inertia ixx="0.00001" ixy="0.0" ixz="0.0" iyy="0.00001" iyz="0.0" izz="0.00001"/>
      <mass value="0.1"/>
      <origin rpy="0 0 0" xyz="0 0 0"/>
    </inertial>
    <visual>
      <geometry>
        <mesh filename="file:///home/dfki.uni-bremen.de/mlodhi/WasteShark/catkin_ws/src/uuv_simulator/uuv_sensor_plugins/uuv_sensor_ros_plugins/meshes/oe14-372.dae" scale="1.0 1.0 1.0"/>
      </geometry>
    </visual>
    <collision>
      <geometry>
        <cylinder length="1e-06" radius="1e-06"/>
      </geometry>
      <origin rpy="0 1.57079632679 0" xyz="0 0 0"/>
    </collision>
  </link>
  <joint name="dory/camera_joint" type="revolute">
    <origin rpy="-1.5708 0.0 -1.5708 " xyz="0.7 0 0.4"/>
    <parent link="dory/base_link"/>
    <child link="dory/camera_link"/>
    <limit effort="0" lower="0" upper="0" velocity="0"/>
    <axis xyz="1 0 0"/>
  </joint>
  <link name="dory/camera_link_optical">
    <inertial>
      <mass value="0.001"/>
      <origin rpy="0 0 0" xyz="0 0 0"/>
      <inertia ixx="1.666666e-12" ixy="0.0" ixz="0.0" iyy="1.666666e-12" iyz="0.0" izz="1.666666e-12"/>
    </inertial>
    <collision>

      <geometry>
        <cylinder length="0.000001" radius="0.000001"/>
      </geometry>
      <origin rpy="0 1.57079632679 0" xyz="0 0 0"/>
    </collision>
  </link>
  <joint name="dory/camera_optical_joint" type="revolute">
    <origin rpy="-1.57079632679 0 -1.57079632679" xyz="0 0 0"/>
    <parent link="dory/camera_link"/>
    <child link="dory/camera_link_optical"/>
    <limit effort="0" lower="0" upper="0" velocity="0"/>
    <axis xyz="1 0 0"/>
  </joint>

  <!-- GPS link -->
  <link name="dory/gps_link">
    <inertial>
      <inertia ixx="0.00001" ixy="0.0" ixz="0.0" iyy="0.00001" iyz="0.0" izz="0.00001"/>
      <mass value="0.001"/>
      <!-- [kg] -->
      <origin rpy="0 0 0" xyz="0 0 0"/>
    </inertial>
  </link>
  <!-- GPS joint -->
  <joint name="dory/gps_joint" type="revolute">
    <origin rpy="0 0 0" xyz="0 0 0"/>
    <parent link="dory/base_link"/>
    <child link="dory/gps_link"/>
    <axis xyz="1 0 0"/>
    <limit effort="0" lower="0" upper="0" velocity="0"/>
  </joint>

</robot>
